<?xml version="1.0" ?>
<sdf version="1.7">
    <world name="car_world">
        <physics name="1ms" type="ignored">
            <max_step_size>0.001</max_step_size>
            <real_time_factor>1.0</real_time_factor>
        </physics>
        <plugin
            filename="libignition-gazebo-physics-system.so"
            name="ignition::gazebo::systems::Physics">
        </plugin>
        <plugin
            filename="libignition-gazebo-user-commands-system.so"
            name="ignition::gazebo::systems::UserCommands">
        </plugin>
        <plugin
            filename="libignition-gazebo-scene-broadcaster-system.so"
            name="ignition::gazebo::systems::SceneBroadcaster">
        </plugin>

        <gui fullscreen="0">

            <!-- 3D scene -->
            <plugin filename="GzScene3D" name="3D View">
                <ignition-gui>
                <title>3D View</title>
                <property type="bool" key="showTitleBar">false</property>
                <property type="string" key="state">docked</property>
                </ignition-gui>

                <engine>ogre2</engine>
                <scene>scene</scene>
                <ambient_light>0.4 0.4 0.4</ambient_light>
                <background_color>0.8 0.8 0.8</background_color>
            </plugin>

            <!-- World control -->
            <plugin filename="WorldControl" name="World control">
                <ignition-gui>
                <title>World control</title>
                <property type="bool" key="showTitleBar">false</property>
                <property type="bool" key="resizable">false</property>
                <property type="double" key="height">72</property>
                <property type="double" key="width">121</property>
                <property type="double" key="z">1</property>

                <property type="string" key="state">floating</property>
                <anchors target="3D View">
                    <line own="left" target="left"/>
                    <line own="bottom" target="bottom"/>
                </anchors>
                </ignition-gui>

                <play_pause>true</play_pause>
                <step>true</step>
                <start_paused>true</start_paused>
                <service>/world/car_world/control</service>
                <stats_topic>/world/car_world/stats</stats_topic>
            </plugin>

            <!-- World statistics -->
            <plugin filename="WorldStats" name="World stats">
                <ignition-gui>
                <title>World stats</title>
                <property type="bool" key="showTitleBar">false</property>
                <property type="bool" key="resizable">false</property>
                <property type="double" key="height">110</property>
                <property type="double" key="width">290</property>
                <property type="double" key="z">1</property>

                <property type="string" key="state">floating</property>
                <anchors target="3D View">
                    <line own="right" target="right"/>
                    <line own="bottom" target="bottom"/>
                </anchors>
                </ignition-gui>

                <sim_time>true</sim_time>
                <real_time>true</real_time>
                <real_time_factor>true</real_time_factor>
                <iterations>true</iterations>
                <topic>/world/car_world/stats</topic>

            </plugin>

            <!-- Entity tree -->
            <plugin filename="EntityTree" name="Entity tree">
            </plugin>

        </gui>

        <light type="directional" name="sun">
            <cast_shadows>true</cast_shadows>
            <pose>0 0 10 0 0 0</pose>
            <diffuse>0.8 0.8 0.8 1</diffuse>
            <specular>0.2 0.2 0.2 1</specular>
            <attenuation>
                <range>1000</range>
                <constant>0.9</constant>
                <linear>0.01</linear>
                <quadratic>0.001</quadratic>
            </attenuation>
            <direction>-0.5 0.1 -0.9</direction>
        </light>

        <model name="ground_plane">
            <static>true</static>
            <link name="link">
                <collision name="collision">
                <geometry>
                    <plane>
                    <normal>0 0 1</normal>
                    </plane>
                </geometry>
                </collision>
                <visual name="visual">
                <geometry>
                    <plane>
                    <normal>0 0 1</normal>
                    <size>100 100</size>
                    </plane>
                </geometry>
                <material>
                    <ambient>0.8 0.8 0.8 1</ambient>
                    <diffuse>0.8 0.8 0.8 1</diffuse>
                    <specular>0.8 0.8 0.8 1</specular>
                </material>
                </visual>
            </link>
        </model>

        <model name='LRMate-200iD' canonical_link='cube'>
            <include>
                <uri>file://./lrmate_200id.sdf</uri>  <!--it also can be included from model://-->
                <pose>0 0 0.4 0 0 0</pose>
            </include>

            <self_collide>true</self_collide> <!--There must need collision tag in the model?-->

            <pose relative_to='world'>0 0 0.4 0 0 0</pose>  <!--center position-->
            <link name='cube'>
                <inertial>
                    <mass>20.14395</mass>
                    <inertia>
                        <ixx>0.095329</ixx>
                        <ixy>0</ixy>
                        <ixz>0</ixz>
                        <iyy>0.381317</iyy>
                        <iyz>0</iyz>
                        <izz>0.476646</izz>
                    </inertia>
                </inertial>
                <visual name='visual'>
                    <geometry>
                        <box>
                            <size>0.8 0.8 0.8</size>
                        </box>
                    </geometry>
                    <!--let's add color to our link-->
                    <material>
                        <ambient>0.5 0.5 0.5 1</ambient>
                        <diffuse>0.5 0.5 0.5 1</diffuse>
                        <specular>0.5 0.5 0.5 1</specular>
                    </material>
                </visual>
                <collision name='collision'>
                    <geometry>
                        <box>
                            <size>0.8 0.8 0.8</size>
                        </box>
                    </geometry>
                </collision>
            </link>

            <joint name="table_fixed_to_world" type="fixed">
                <pose>0 0 0 0 0 0</pose>
                <parent>world</parent>
                <child>cube</child>
            </joint>

            <joint name="arm_fixed_to_table" type="fixed">
                <pose>0 0 0.4 0 0 0</pose>
                <parent>cube</parent>
                <child>lrmate_200id::Base</child>
            </joint>

            <!--  Redefining joints to ensure joints can be controlled by Joint controller plugins -->
            <joint name="j1" type="revolute">
                <pose relative_to="cube">0 0 0.4 0 0 0</pose>
                <parent>cube</parent>
                <child>lrmate_200id::L1</child>
                <axis>
                    <xyz>0 0 1</xyz>
                </axis>
            </joint>

            <joint name="j2" type="revolute">
                <pose relative_to='lrmate_200id::L1'>0.05 0 0.28726 0 -0 0</pose>
                <parent>lrmate_200id::L1</parent>
                <child>lrmate_200id::L2</child>
                <axis>
                    <xyz>0 -1 0</xyz>
                </axis>
            </joint>

            <joint name="j3" type="revolute">
                <pose relative_to='lrmate_200id::L2'>0 0 0.33 0 -0 0</pose>
                <parent>lrmate_200id::L2</parent>
                <child>lrmate_200id::L3</child>
                <axis>
                    <xyz>0 -1 0</xyz>
                </axis>
            </joint>

            <joint name="j4" type="revolute">
                <pose relative_to='lrmate_200id::L3'>0.088001 0 0.035027 0 -0 0</pose>
                <parent>lrmate_200id::L3</parent>
                <child>lrmate_200id::L4</child>
                <axis>
                    <xyz>1 0 0</xyz>
                </axis>
            </joint>

            <joint name="j5" type="revolute">
                <pose relative_to='lrmate_200id::L4'>0.2454 0 0 0 -0 0</pose>
                <parent>lrmate_200id::L4</parent>
                <child>lrmate_200id::L5</child>
                <axis>
                    <xyz>0 -1 0</xyz>
                </axis>
            </joint>

            <joint name="j6" type="revolute">
                <pose relative_to='lrmate_200id::L5'>0.05 0 0 1.5708 -0 0</pose>
                <parent>lrmate_200id::L5</parent>
                <child>lrmate_200id::L6</child>
                <axis>
                    <xyz>-1 0 0</xyz>
                </axis>
            </joint>

            <!-- Joint controller plugins -->
            <plugin filename="ignition-gazebo-joint-controller-system" name="ignition::gazebo::systems::JointController">
                <joint_name>j1</joint_name>
                <initial_velocity>1.0</initial_velocity>
                <topic>j1</topic>
            </plugin>

            <plugin filename="ignition-gazebo-joint-position-controller-system" name="ignition::gazebo::systems::JointPositionController">
                <joint_name>j2</joint_name>
                <topic>j2</topic>
                <p_gain>10000</p_gain>
                <d_gain>500</d_gain>
                <i_gain>0</i_gain>
                <i_min>-1</i_min>
                <i_max>1</i_max>
                <cmd_min>-87</cmd_min>
                <cmd_max>87</cmd_max>
                <initial_position>-0.5</initial_position>
            </plugin>

            <!--<plugin filename="ignition-gazebo-joint-controller-system" name="ignition::gazebo::systems::JointController">
                <joint_name>j2</joint_name>
                <initial_velocity>-0.0</initial_velocity>
                <topic>j2</topic>
            </plugin>-->

            <plugin filename="ignition-gazebo-joint-controller-system" name="ignition::gazebo::systems::JointController">
                <joint_name>j3</joint_name>
                <initial_velocity>-4.0</initial_velocity>
                <topic>j3</topic>
            </plugin>

            <plugin filename="ignition-gazebo-joint-controller-system" name="ignition::gazebo::systems::JointController">
                <joint_name>j4</joint_name>
                <initial_velocity>1.0</initial_velocity>
                <topic>j4</topic>
            </plugin>

            <plugin filename="ignition-gazebo-joint-controller-system" name="ignition::gazebo::systems::JointController">
                <joint_name>j5</joint_name>
                <initial_velocity>-1.0</initial_velocity>
                <topic>j5</topic>
            </plugin>

            <plugin filename="ignition-gazebo-joint-controller-system" name="ignition::gazebo::systems::JointController">
                <joint_name>j6</joint_name>
                <initial_velocity>-0.0</initial_velocity>
                <topic>j6</topic>
            </plugin>
        </model>

        <model name='ConveyorBelt'>
            <include>
                <uri>file://./ConveyorBelt.sdf</uri>  <!--it also can be included from model://-->
                <pose>0.4 -1 0 1.57 0 1.57</pose>
            </include>
            
            <joint name="belt_fixed_to_world" type="fixed">
                <pose>0 0 0 0 0 0</pose>
                <parent>world</parent>
                <child>Belt::belt</child>
            </joint>
        </model>
    </world>
</sdf>